<?xml version="1.0" encoding="utf-8"?>
<robot name="u_bot">

	<link name="robot_caster_wheel_1">
		<visual>
			<origin xyz="0 0 0" rpy="0 0 0" />
			<geometry>
				<mesh filename="package://description/meshes/caster_wheel.stl" />
			</geometry>
			<material name="Red" />
		</visual>
		<collision>
			<origin xyz="0 0 0" rpy="0 0 0" />
			<geometry>
				<mesh filename="package://description/meshes/caster_wheel.stl" />
			</geometry>
		</collision>
	</link>

	<link name="robot_caster_wheel_2">
		<visual>
			<origin xyz="0 0 0" rpy="0 0 0" />
			<geometry>
				<mesh filename="package://description/meshes/caster_wheel.stl" />
			</geometry>
			<material name="Red" />
		</visual>
		<collision>
			<origin xyz="0 0 0" rpy="0 0 0" />
			<geometry>
				<mesh filename="package://description/meshes/caster_wheel.stl" />
			</geometry>
		</collision>
	</link>



	<joint name="caster_wheel_1_to_base" type="continuous">
		<origin xyz="-0.13 0 -0.015" rpy="0 0 0" />
		<parent link="robot_base" />
		<child link="robot_caster_wheel_1" />
		<axis xyz="1 1 0" />
	</joint>

	<joint name="caster_wheel_2_to_base" type="continuous">
		<origin xyz="0.13 0 -0.015" rpy="0 0 0" />
		<parent link="robot_base" />
		<child link="robot_caster_wheel_2" />
		<axis xyz="1 1 0" />
	</joint>
</robot>
