<?xml version="1.0" encoding="utf-8"?>
<robot name="u_bot">

	<link name="robot_right_wheel">
		<visual>
			<origin xyz="0 0 0" rpy="0 0 0" />
			<geometry>
				<mesh filename="package://description/meshes/right_wheel.stl" />
			</geometry>
			<material name="Red" />
		</visual>
		<collision>
			<origin xyz="0 0 0" rpy="0 0 0" />
			<geometry>
				<mesh filename="package://description/meshes/right_wheel.stl" />
			</geometry>
		</collision>
	</link>

	<link name="right_wheel">
		<visual>
			<origin xyz="0 0 0" rpy="${PI/2} 0 0" />
			<geometry>
				<cylinder length="${wheel_width}" radius="${wheel_radius}"/>
			</geometry>
			<material name="Red" />
		</visual>
		<collision>
			<origin xyz="0 0 0" rpy="${PI/2} 0 0" />
			<geometry>
				<cylinder length="${wheel_width}" radius="${wheel_radius}"/>
			</geometry>
		</collision>
	</link>

	<joint name="right_wheel_to_robot_right_wheel" type="fixed">
		<origin xyz="0 0 0" rpy="0 0 0" />
		<parent link="right_wheel" />
		<child link="robot_right_wheel" />
	</joint>
	
	<joint name="right_wheel_to_base" type="continuous">
		<origin xyz="0 -0.195 0.03" rpy="0 0 0" />
		<parent link="robot_base" />
		<child link="right_wheel" />
		<axis xyz="0 1 0" />
	</joint>
</robot>
